2021-05-04 22:34:23,808 ERROR: Exception on / [GET] [in c:\users\abrow\appdata\local\programs\python\python37-32\lib\site-packages\flask\app.py:1892]
Traceback (most recent call last):
  File "c:\users\abrow\appdata\local\programs\python\python37-32\lib\site-packages\flask\app.py", line 2447, in wsgi_app
    response = self.full_dispatch_request()
  File "c:\users\abrow\appdata\local\programs\python\python37-32\lib\site-packages\flask\app.py", line 1952, in full_dispatch_request
    rv = self.handle_user_exception(e)
  File "c:\users\abrow\appdata\local\programs\python\python37-32\lib\site-packages\flask\app.py", line 1821, in handle_user_exception
    reraise(exc_type, exc_value, tb)
  File "c:\users\abrow\appdata\local\programs\python\python37-32\lib\site-packages\flask\_compat.py", line 39, in reraise
    raise value
  File "c:\users\abrow\appdata\local\programs\python\python37-32\lib\site-packages\flask\app.py", line 1950, in full_dispatch_request
    rv = self.dispatch_request()
  File "c:\users\abrow\appdata\local\programs\python\python37-32\lib\site-packages\flask\app.py", line 1936, in dispatch_request
    return self.view_functions[rule.endpoint](**req.view_args)
  File "c:\users\abrow\appdata\local\programs\python\python37-32\lib\site-packages\flask_login\utils.py", line 271, in decorated_view
    return current_app.login_manager.unauthorized()
  File "c:\users\abrow\appdata\local\programs\python\python37-32\lib\site-packages\flask_login\login_manager.py", line 174, in unauthorized
    redirect_url = make_login_url(login_view, next_url=request.url)
  File "c:\users\abrow\appdata\local\programs\python\python37-32\lib\site-packages\flask_login\utils.py", line 120, in login_url
    base = expand_login_view(login_view)
  File "c:\users\abrow\appdata\local\programs\python\python37-32\lib\site-packages\flask_login\utils.py", line 97, in expand_login_view
    return url_for(login_view)
  File "c:\users\abrow\appdata\local\programs\python\python37-32\lib\site-packages\flask\helpers.py", line 370, in url_for
    return appctx.app.handle_url_build_error(error, endpoint, values)
  File "c:\users\abrow\appdata\local\programs\python\python37-32\lib\site-packages\flask\app.py", line 2216, in handle_url_build_error
    reraise(exc_type, exc_value, tb)
  File "c:\users\abrow\appdata\local\programs\python\python37-32\lib\site-packages\flask\_compat.py", line 39, in reraise
    raise value
  File "c:\users\abrow\appdata\local\programs\python\python37-32\lib\site-packages\flask\helpers.py", line 358, in url_for
    endpoint, values, method=method, force_external=external
  File "c:\users\abrow\appdata\local\programs\python\python37-32\lib\site-packages\werkzeug\routing.py", line 2179, in build
    raise BuildError(endpoint, values, method, self)
werkzeug.routing.BuildError: Could not build url for endpoint 'login'. Did you mean 'auth.login' instead?
2021-05-04 22:38:33,720 INFO: Microblog startup [in D:\Google Drive\Coding\Web Development\microblog\app\__init__.py:74]
2021-05-04 22:38:42,409 ERROR: Exception on / [GET] [in c:\users\abrow\appdata\local\programs\python\python37-32\lib\site-packages\flask\app.py:1892]
Traceback (most recent call last):
  File "c:\users\abrow\appdata\local\programs\python\python37-32\lib\site-packages\flask\app.py", line 2447, in wsgi_app
    response = self.full_dispatch_request()
  File "c:\users\abrow\appdata\local\programs\python\python37-32\lib\site-packages\flask\app.py", line 1952, in full_dispatch_request
    rv = self.handle_user_exception(e)
  File "c:\users\abrow\appdata\local\programs\python\python37-32\lib\site-packages\flask\app.py", line 1821, in handle_user_exception
    reraise(exc_type, exc_value, tb)
  File "c:\users\abrow\appdata\local\programs\python\python37-32\lib\site-packages\flask\_compat.py", line 39, in reraise
    raise value
  File "c:\users\abrow\appdata\local\programs\python\python37-32\lib\site-packages\flask\app.py", line 1950, in full_dispatch_request
    rv = self.dispatch_request()
  File "c:\users\abrow\appdata\local\programs\python\python37-32\lib\site-packages\flask\app.py", line 1936, in dispatch_request
    return self.view_functions[rule.endpoint](**req.view_args)
  File "c:\users\abrow\appdata\local\programs\python\python37-32\lib\site-packages\flask_login\utils.py", line 271, in decorated_view
    return current_app.login_manager.unauthorized()
  File "c:\users\abrow\appdata\local\programs\python\python37-32\lib\site-packages\flask_login\login_manager.py", line 174, in unauthorized
    redirect_url = make_login_url(login_view, next_url=request.url)
  File "c:\users\abrow\appdata\local\programs\python\python37-32\lib\site-packages\flask_login\utils.py", line 120, in login_url
    base = expand_login_view(login_view)
  File "c:\users\abrow\appdata\local\programs\python\python37-32\lib\site-packages\flask_login\utils.py", line 97, in expand_login_view
    return url_for(login_view)
  File "c:\users\abrow\appdata\local\programs\python\python37-32\lib\site-packages\flask\helpers.py", line 370, in url_for
    return appctx.app.handle_url_build_error(error, endpoint, values)
  File "c:\users\abrow\appdata\local\programs\python\python37-32\lib\site-packages\flask\app.py", line 2216, in handle_url_build_error
    reraise(exc_type, exc_value, tb)
  File "c:\users\abrow\appdata\local\programs\python\python37-32\lib\site-packages\flask\_compat.py", line 39, in reraise
    raise value
  File "c:\users\abrow\appdata\local\programs\python\python37-32\lib\site-packages\flask\helpers.py", line 358, in url_for
    endpoint, values, method=method, force_external=external
  File "c:\users\abrow\appdata\local\programs\python\python37-32\lib\site-packages\werkzeug\routing.py", line 2179, in build
    raise BuildError(endpoint, values, method, self)
werkzeug.routing.BuildError: Could not build url for endpoint 'login'. Did you mean 'auth.login' instead?
2021-05-04 22:41:10,736 INFO: Microblog startup [in D:\Google Drive\Coding\Web Development\microblog\app\__init__.py:74]
2021-05-04 22:42:41,329 ERROR: Exception on /auth/reset_password_request [POST] [in c:\users\abrow\appdata\local\programs\python\python37-32\lib\site-packages\flask\app.py:1892]
Traceback (most recent call last):
  File "c:\users\abrow\appdata\local\programs\python\python37-32\lib\site-packages\flask\app.py", line 2447, in wsgi_app
    response = self.full_dispatch_request()
  File "c:\users\abrow\appdata\local\programs\python\python37-32\lib\site-packages\flask\app.py", line 1952, in full_dispatch_request
    rv = self.handle_user_exception(e)
  File "c:\users\abrow\appdata\local\programs\python\python37-32\lib\site-packages\flask\app.py", line 1821, in handle_user_exception
    reraise(exc_type, exc_value, tb)
  File "c:\users\abrow\appdata\local\programs\python\python37-32\lib\site-packages\flask\_compat.py", line 39, in reraise
    raise value
  File "c:\users\abrow\appdata\local\programs\python\python37-32\lib\site-packages\flask\app.py", line 1950, in full_dispatch_request
    rv = self.dispatch_request()
  File "c:\users\abrow\appdata\local\programs\python\python37-32\lib\site-packages\flask\app.py", line 1936, in dispatch_request
    return self.view_functions[rule.endpoint](**req.view_args)
  File "D:\Google Drive\Coding\Web Development\microblog\app\auth\routes.py", line 61, in reset_password_request
    send_password_reset_email(user)
  File "D:\Google Drive\Coding\Web Development\microblog\app\auth\email.py", line 7, in send_password_reset_email
    token = user.get_reset_password_token()
  File "D:\Google Drive\Coding\Web Development\microblog\app\models.py", line 67, in get_reset_password_token
    app.config['SECRET_KEY'], algorithm='HS256').decode('utf-8')
AttributeError: 'str' object has no attribute 'decode'
2021-05-04 22:45:13,110 INFO: Microblog startup [in D:\Google Drive\Coding\Web Development\microblog\app\__init__.py:74]
2021-05-04 22:45:17,383 ERROR: Exception on /auth/reset_password_request [POST] [in c:\users\abrow\appdata\local\programs\python\python37-32\lib\site-packages\flask\app.py:1892]
Traceback (most recent call last):
  File "c:\users\abrow\appdata\local\programs\python\python37-32\lib\site-packages\flask\app.py", line 2447, in wsgi_app
    response = self.full_dispatch_request()
  File "c:\users\abrow\appdata\local\programs\python\python37-32\lib\site-packages\flask\app.py", line 1952, in full_dispatch_request
    rv = self.handle_user_exception(e)
  File "c:\users\abrow\appdata\local\programs\python\python37-32\lib\site-packages\flask\app.py", line 1821, in handle_user_exception
    reraise(exc_type, exc_value, tb)
  File "c:\users\abrow\appdata\local\programs\python\python37-32\lib\site-packages\flask\_compat.py", line 39, in reraise
    raise value
  File "c:\users\abrow\appdata\local\programs\python\python37-32\lib\site-packages\flask\app.py", line 1950, in full_dispatch_request
    rv = self.dispatch_request()
  File "c:\users\abrow\appdata\local\programs\python\python37-32\lib\site-packages\flask\app.py", line 1936, in dispatch_request
    return self.view_functions[rule.endpoint](**req.view_args)
  File "D:\Google Drive\Coding\Web Development\microblog\app\auth\routes.py", line 61, in reset_password_request
    send_password_reset_email(user)
  File "D:\Google Drive\Coding\Web Development\microblog\app\auth\email.py", line 7, in send_password_reset_email
    token = user.get_reset_password_token()
  File "D:\Google Drive\Coding\Web Development\microblog\app\models.py", line 67, in get_reset_password_token
    current_app.config['SECRET_KEY'],
NameError: name 'current_app' is not defined
2021-05-04 22:46:18,036 INFO: Microblog startup [in D:\Google Drive\Coding\Web Development\microblog\app\__init__.py:74]
