2021-04-29 12:38:17,224 INFO: Microblog startup [in D:\Google Drive\Coding\Web Development\microblog\app\__init__.py:42]
2021-04-29 12:38:24,382 ERROR: Exception on / [GET] [in c:\users\abrow\appdata\local\programs\python\python37-32\lib\site-packages\flask\app.py:1892]
Traceback (most recent call last):
  File "c:\users\abrow\appdata\local\programs\python\python37-32\lib\site-packages\flask\app.py", line 2447, in wsgi_app
    response = self.full_dispatch_request()
  File "c:\users\abrow\appdata\local\programs\python\python37-32\lib\site-packages\flask\app.py", line 1952, in full_dispatch_request
    rv = self.handle_user_exception(e)
  File "c:\users\abrow\appdata\local\programs\python\python37-32\lib\site-packages\flask\app.py", line 1821, in handle_user_exception
    reraise(exc_type, exc_value, tb)
  File "c:\users\abrow\appdata\local\programs\python\python37-32\lib\site-packages\flask\_compat.py", line 39, in reraise
    raise value
  File "c:\users\abrow\appdata\local\programs\python\python37-32\lib\site-packages\flask\app.py", line 1950, in full_dispatch_request
    rv = self.dispatch_request()
  File "c:\users\abrow\appdata\local\programs\python\python37-32\lib\site-packages\flask\app.py", line 1936, in dispatch_request
    return self.view_functions[rule.endpoint](**req.view_args)
  File "c:\users\abrow\appdata\local\programs\python\python37-32\lib\site-packages\flask_login\utils.py", line 272, in decorated_view
    return func(*args, **kwargs)
  File "D:\Google Drive\Coding\Web Development\microblog\app\routes.py", line 28, in index
    posts = current_user.followed.posts().all()
AttributeError: 'AppenderBaseQuery' object has no attribute 'posts'
2021-04-29 12:38:33,336 ERROR: Exception on /explore [GET] [in c:\users\abrow\appdata\local\programs\python\python37-32\lib\site-packages\flask\app.py:1892]
Traceback (most recent call last):
  File "c:\users\abrow\appdata\local\programs\python\python37-32\lib\site-packages\flask\app.py", line 2447, in wsgi_app
    response = self.full_dispatch_request()
  File "c:\users\abrow\appdata\local\programs\python\python37-32\lib\site-packages\flask\app.py", line 1952, in full_dispatch_request
    rv = self.handle_user_exception(e)
  File "c:\users\abrow\appdata\local\programs\python\python37-32\lib\site-packages\flask\app.py", line 1821, in handle_user_exception
    reraise(exc_type, exc_value, tb)
  File "c:\users\abrow\appdata\local\programs\python\python37-32\lib\site-packages\flask\_compat.py", line 39, in reraise
    raise value
  File "c:\users\abrow\appdata\local\programs\python\python37-32\lib\site-packages\flask\app.py", line 1950, in full_dispatch_request
    rv = self.dispatch_request()
  File "c:\users\abrow\appdata\local\programs\python\python37-32\lib\site-packages\flask\app.py", line 1936, in dispatch_request
    return self.view_functions[rule.endpoint](**req.view_args)
  File "c:\users\abrow\appdata\local\programs\python\python37-32\lib\site-packages\flask_login\utils.py", line 272, in decorated_view
    return func(*args, **kwargs)
  File "D:\Google Drive\Coding\Web Development\microblog\app\routes.py", line 136, in explore
    return render_template('index.html', title='Explore', posts=posts)
  File "c:\users\abrow\appdata\local\programs\python\python37-32\lib\site-packages\flask\templating.py", line 138, in render_template
    ctx.app.jinja_env.get_or_select_template(template_name_or_list),
  File "c:\users\abrow\appdata\local\programs\python\python37-32\lib\site-packages\jinja2\environment.py", line 930, in get_or_select_template
    return self.get_template(template_name_or_list, parent, globals)
  File "c:\users\abrow\appdata\local\programs\python\python37-32\lib\site-packages\jinja2\environment.py", line 883, in get_template
    return self._load_template(name, self.make_globals(globals))
  File "c:\users\abrow\appdata\local\programs\python\python37-32\lib\site-packages\jinja2\environment.py", line 857, in _load_template
    template = self.loader.load(self, name, globals)
  File "c:\users\abrow\appdata\local\programs\python\python37-32\lib\site-packages\jinja2\loaders.py", line 127, in load
    code = environment.compile(source, name, filename)
  File "c:\users\abrow\appdata\local\programs\python\python37-32\lib\site-packages\jinja2\environment.py", line 638, in compile
    self.handle_exception(source=source_hint)
  File "c:\users\abrow\appdata\local\programs\python\python37-32\lib\site-packages\jinja2\environment.py", line 832, in handle_exception
    reraise(*rewrite_traceback_stack(source=source))
  File "c:\users\abrow\appdata\local\programs\python\python37-32\lib\site-packages\jinja2\_compat.py", line 28, in reraise
    raise value.with_traceback(tb)
  File "D:\Google Drive\Coding\Web Development\microblog\app\templates\index.html", line 24, in template
    {% endfor %}
jinja2.exceptions.TemplateSyntaxError: Encountered unknown tag 'endfor'. Jinja was looking for the following tags: 'endblock'. The innermost block that needs to be closed is 'block'.
2021-04-29 12:41:06,880 INFO: Microblog startup [in D:\Google Drive\Coding\Web Development\microblog\app\__init__.py:42]
2021-04-29 12:41:10,012 ERROR: Exception on /index [GET] [in c:\users\abrow\appdata\local\programs\python\python37-32\lib\site-packages\flask\app.py:1892]
Traceback (most recent call last):
  File "c:\users\abrow\appdata\local\programs\python\python37-32\lib\site-packages\flask\app.py", line 2447, in wsgi_app
    response = self.full_dispatch_request()
  File "c:\users\abrow\appdata\local\programs\python\python37-32\lib\site-packages\flask\app.py", line 1952, in full_dispatch_request
    rv = self.handle_user_exception(e)
  File "c:\users\abrow\appdata\local\programs\python\python37-32\lib\site-packages\flask\app.py", line 1821, in handle_user_exception
    reraise(exc_type, exc_value, tb)
  File "c:\users\abrow\appdata\local\programs\python\python37-32\lib\site-packages\flask\_compat.py", line 39, in reraise
    raise value
  File "c:\users\abrow\appdata\local\programs\python\python37-32\lib\site-packages\flask\app.py", line 1950, in full_dispatch_request
    rv = self.dispatch_request()
  File "c:\users\abrow\appdata\local\programs\python\python37-32\lib\site-packages\flask\app.py", line 1936, in dispatch_request
    return self.view_functions[rule.endpoint](**req.view_args)
  File "c:\users\abrow\appdata\local\programs\python\python37-32\lib\site-packages\flask_login\utils.py", line 272, in decorated_view
    return func(*args, **kwargs)
  File "D:\Google Drive\Coding\Web Development\microblog\app\routes.py", line 28, in index
    posts = current_user.followed.posts().all()
AttributeError: 'AppenderBaseQuery' object has no attribute 'posts'
2021-04-29 12:41:16,402 ERROR: Exception on /index [GET] [in c:\users\abrow\appdata\local\programs\python\python37-32\lib\site-packages\flask\app.py:1892]
Traceback (most recent call last):
  File "c:\users\abrow\appdata\local\programs\python\python37-32\lib\site-packages\flask\app.py", line 2447, in wsgi_app
    response = self.full_dispatch_request()
  File "c:\users\abrow\appdata\local\programs\python\python37-32\lib\site-packages\flask\app.py", line 1952, in full_dispatch_request
    rv = self.handle_user_exception(e)
  File "c:\users\abrow\appdata\local\programs\python\python37-32\lib\site-packages\flask\app.py", line 1821, in handle_user_exception
    reraise(exc_type, exc_value, tb)
  File "c:\users\abrow\appdata\local\programs\python\python37-32\lib\site-packages\flask\_compat.py", line 39, in reraise
    raise value
  File "c:\users\abrow\appdata\local\programs\python\python37-32\lib\site-packages\flask\app.py", line 1950, in full_dispatch_request
    rv = self.dispatch_request()
  File "c:\users\abrow\appdata\local\programs\python\python37-32\lib\site-packages\flask\app.py", line 1936, in dispatch_request
    return self.view_functions[rule.endpoint](**req.view_args)
  File "c:\users\abrow\appdata\local\programs\python\python37-32\lib\site-packages\flask_login\utils.py", line 272, in decorated_view
    return func(*args, **kwargs)
  File "D:\Google Drive\Coding\Web Development\microblog\app\routes.py", line 28, in index
    posts = current_user.followed.posts().all()
AttributeError: 'AppenderBaseQuery' object has no attribute 'posts'
2021-04-29 12:41:23,154 ERROR: Exception on /index [GET] [in c:\users\abrow\appdata\local\programs\python\python37-32\lib\site-packages\flask\app.py:1892]
Traceback (most recent call last):
  File "c:\users\abrow\appdata\local\programs\python\python37-32\lib\site-packages\flask\app.py", line 2447, in wsgi_app
    response = self.full_dispatch_request()
  File "c:\users\abrow\appdata\local\programs\python\python37-32\lib\site-packages\flask\app.py", line 1952, in full_dispatch_request
    rv = self.handle_user_exception(e)
  File "c:\users\abrow\appdata\local\programs\python\python37-32\lib\site-packages\flask\app.py", line 1821, in handle_user_exception
    reraise(exc_type, exc_value, tb)
  File "c:\users\abrow\appdata\local\programs\python\python37-32\lib\site-packages\flask\_compat.py", line 39, in reraise
    raise value
  File "c:\users\abrow\appdata\local\programs\python\python37-32\lib\site-packages\flask\app.py", line 1950, in full_dispatch_request
    rv = self.dispatch_request()
  File "c:\users\abrow\appdata\local\programs\python\python37-32\lib\site-packages\flask\app.py", line 1936, in dispatch_request
    return self.view_functions[rule.endpoint](**req.view_args)
  File "c:\users\abrow\appdata\local\programs\python\python37-32\lib\site-packages\flask_login\utils.py", line 272, in decorated_view
    return func(*args, **kwargs)
  File "D:\Google Drive\Coding\Web Development\microblog\app\routes.py", line 28, in index
    posts = current_user.followed.posts().all()
AttributeError: 'AppenderBaseQuery' object has no attribute 'posts'
2021-04-29 12:41:54,431 INFO: Microblog startup [in D:\Google Drive\Coding\Web Development\microblog\app\__init__.py:42]
